Workbook

Sheet Cover
B2: SLNG LNG TANK FARM EXPANSION — PHASE 2
B3: Financial Model — InvestIQ Production Grade | Version 1.0 | April 2025
B5: Project | D5: SLNG LNG Tank Farm Expansion — Phase 2
B6: Operator | D6: Singapore LNG Corporation Pte Ltd (SLNG)
B7: Location | D7: Jurong Island, Singapore
B8: Capacity | D8: 2 × 200,000 m³ full-containment LNG storage tanks
B9: Total Capex | D9: USD 850M (Base) / USD 918M (Contingency-inclusive)
B10: Construction | D10: 2025 – 2027 (30 months)
B11: Operations | D11: 2028 – 2044 (17 years)
B12: Financing | D12: 65% Project Finance Debt (USD 552.5M) / 35% Equity (USD 297.5M)
B13: Base WACC | D13: 8.5%
B14: Project IRR | D14: 12.3% (Base Case)
B15: Equity IRR | D15: 15.8% (Base Case)
B16: NPV @ WACC | D16: USD 145M
... B21: Status | D21: APPROVED FOR IC SUBMISSION
B24: WORKBOOK STRUCTURE
B25: Cover | D25: Project overview, metadata, sheet navigation
B26: Assumptions | D26: All hardcoded inputs, scenario toggles, source annotations
B27: Macro_Scenarios | D27: Base / Stress / Upside / Monte Carlo scenario sets
B28: Revenue | D28: Throughput fees, storage, ancillary revenue build-up
B29: Capex | D29: Construction capex by package, maintenance capex schedule
B30: Opex | D30: Operating cost components, inflation escalation
B31: PnL | D31: P&L: Revenue, EBITDA, EBIT, EBT, Net Income
B32: Balance_Sheet | D32: Assets, liabilities, equity — annual balance sheet
B33: CashFlows | D33: Free cash flow, equity cash flow, unlevered FCF
B34: Debt_Schedule | D34: Drawdown, amortisation, interest, DSCR, DSRA
B35: Depreciation | D35: Asset register, depreciation by component
B36: Tax_Schedule | D36: Corporate tax, capital allowances (S.19 ITA), deferred tax
... B43: Dashboard | D43: Executive KPI dashboard — linked from all sheets

Sheet Assumptions
B2: KEY ASSUMPTIONS — ALL INPUTS
B3: Row | C3: Assumption | D3: Value | E3: Unit | F3: Source / Reference | G3: Scenario (Base/Stress/Upside)
B4: ── PROJECT PARAMETERS
B5: A1 | C5: Project name | D5: SLNG LNG Tank Farm Expansion Phase 2 | F5: Project description
B6: A2 | C6: Financial close year | D6: 2025 | E6: Year | F6: Legal agreements
B7: A3 | C7: Construction period | D7: 3 | E7: Years | F7: EPC contract schedule
B8: A4 | C8: Operations start year | D8: 2028 | E8: Year | F8: Commissioning milestone M8
B9: A5 | C9: Operations end year | D9: 2044 | E9: Year | F9: Concession agreement
B10: A6 | C10: Total project life | D10: =D9-D6+1 -> 20 | E10: Years | F10: Calc
B11: ── CAPITAL EXPENDITURE
B12: B1 | C12: Total base capex | D12: 850 | E12: USD M | F12: FEED report, April 2025 estimate
B13: B2 | C13: Capex contingency % | D13: 0.08 | E13: % of base | F13: EPC risk register, ±8%
B14: B3 | C14: Capex incl. contingency | D14: =D12*(1+D13) -> 918 | E14: USD M | F14: Calc
B15: B4 | C15: Construction year 1 (2025) % | D15: 0.1 | E15: % of total | F15: Detailed construction schedule
B16: B5 | C16: Construction year 2 (2026) % | D16: 0.55 | E16: % of total | F16: Detailed construction schedule
B17: B6 | C17: Construction year 3 (2027) % | D17: 0.35 | E17: % of total | F17: Detailed construction schedule
B18: B7 | C18: Check: sum of capex splits | D18: =D15+D16+D17 -> 1 | E18: (must = 100%) | F18: Integrity check
B19: B8 | C19: Maintenance capex (Year 1-5) | D19: 8.5 | E19: USD M/yr | F19: O&M cost estimate
B20: B9 | C20: Maintenance capex (Year 6-10) | D20: 11 | E20: USD M/yr | F20: O&M cost estimate
B21: B10 | C21: Maintenance capex (Year 11+) | D21: 14.5 | E21: USD M/yr | F21: Major overhaul cycle
B22: ── REVENUE ASSUMPTIONS
B23: C1 | C23: Regasification fee (base) | D23: 0.48 | E23: USD/MMBtu | F23: SP Group HoA, signed Jan 2025
B24: C2 | C24: Throughput fee — Sembcorp | D24: 0.46 | E24: USD/MMBtu | F24: Sembcorp offtake, signed Feb 2025
B25: C3 | C25: Storage fee ($/m³/month) | D25: 0.18 | E25: USD/m³/mo | F25: Storage services agreement
B26: C4 | C26: Ancillary revenue (USD M/yr) | D26: 4.5 | E26: USD M/yr | F26: Admin & ancillary services
B27: C5 | C27: Terminal utilisation — Year 1 | D27: 0.72 | E27: % | F27: Ramp-up period
B28: C6 | C28: Terminal utilisation — Year 2 | D28: 0.82 | E28: % | F28: Ramp-up period
B29: C7 | C29: Terminal utilisation — Steady | D29: 0.87 | E29: % | F29: Long-run average, capacity studies
B30: C8 | C30: Total throughput capacity | D30: 4.5 | E30: MTPA | F30: Design capacity, 2 tanks
B31: C9 | C31: Revenue growth rate (annual) | D31: 0.025 | E31: %/yr | F31: Gas demand forecast, EMA 2024
B32: C10 | C32: SP Group contract duration | D32: 15 | E32: Years | F32: Take-or-pay agreement
B33: C11 | C33: Contracted capacity coverage | D33: 0.78 | E33: % capacity | F33: % under long-term offtake
B34: ── OPERATING COST ASSUMPTIONS
B35: D1 | C35: Fixed opex base (USD M/yr) | D35: 24.5 | E35: USD M/yr | F35: O&M cost model, AECOM 2024
B36: D2 | C36: Variable opex (USD/MMBtu) | D36: 0.042 | E36: USD/MMBtu | F36: Benchmarked to Sg LNG
B37: D3 | C37: Opex inflation rate | D37: 0.025 | E37: %/yr | F37: MAS CPI forecast, 5yr avg
B38: D4 | C38: Insurance (% gross asset value) | D38: 0.006 | E38: %/yr | F38: AON insurance indicative 2025
B39: D5 | C39: Lease/land rental (USD M/yr) | D39: 3.2 | E39: USD M/yr | F39: JTC lease agreement
B40: D6 | C40: G&A overhead (USD M/yr) | D40: 6.8 | E40: USD M/yr | F40: Management allocation
B41: D7 | C41: Regulatory levies (USD M/yr) | D41: 1.5 | E41: USD M/yr | F41: EMA and MAS levies
...

Sheet Revenue
B2: REVENUE MODEL — USD MILLIONS
B3: Revenue Component | C3: 2025 | D3: 2026 | E3: 2027 | F3: 2028 | G3: 2029 | H3: 2030 | I3: 2031 | J3: 2032 | K3: 2033 | L3: 2034 | M3: 2035 | N3: 2036 | O3: 2037 | P3: 2038 | Q3: 2039 | R3: 2040 | S3: 2041 | T3: 2042 | U3: 2043 | V3: 2044
B5: Throughput utilisation | C5: 0 | D5: 0 | E5: 0 | F5: 0.72 | G5: 0.82 | H5: 0.87 | I5: 0.87 | J5: 0.87 | K5: 0.87 | L5: 0.87 | M5: 0.87 | N5: 0.87 | O5: 0.87 | P5: 0.87 | Q5: 0.87 | R5: 0.87 | S5: 0.87 | T5: 0.87 | U5: 0.87 | V5: 0.87
B6: Throughput volume (MMBtu M) | C6: 0 | D6: 0 | E6: 0 | F6: 4.2 | G6: 5.8 | H6: 7.1 | I6: 7.8 | J6: 8.2 | K6: 8.6 | L6: 8.9 | M6: 9.2 | N6: 9.4 | O6: 9.6 | P6: 9.8 | Q6: 10 | R6: 10.1 | S6: 10.2 | T6: 10.3 | U6: 10.3 | V6: 10.4
B7: Regasification fee ($/MMBtu) | C7: 0.48 | D7: 0.48 | E7: 0.48 | F7: 0.48 | G7: 0.48 | H7: 0.48 | I7: 0.48 | J7: 0.48 | K7: 0.48 | L7: 0.48 | M7: 0.48 | N7: 0.48 | O7: 0.48 | P7: 0.48 | Q7: 0.48 | R7: 0.48 | S7: 0.48 | T7: 0.48 | U7: 0.48 | V7: 0.48
B8: SP Group revenue | C8: =IF(C6=0,0,C6*C7*0.78) -> 0 | D8: =IF(D6=0,0,D6*D7*0.78) -> 0 | E8: =IF(E6=0,0,E6*E7*0.78) -> 0 | F8: =IF(F6=0,0,F6*F7*0.78) -> 1.57248 | G8: =IF(G6=0,0,G6*G7*0.78) -> 2.17152 | H8: =IF(H6=0,0,H6*H7*0.78) -> 2.65824 | I8: =IF(I6=0,0,I6*I7*0.78) -> 2.92032 | J8: =IF(J6=0,0,J6*J7*0.78) -> 3.07008 | ... V8: =IF(V6=0,0,V6*V7*0.78) -> 3.89376
B9: Sembcorp revenue | C9: =IF(C6=0,0,C6*0.46*0.22) -> 0 | D9: =IF(D6=0,0,D6*0.46*0.22) -> 0 | E9: =IF(E6=0,0,E6*0.46*0.22) -> 0 | F9: =IF(F6=0,0,F6*0.46*0.22) -> 0.42504 | G9: =IF(G6=0,0,G6*0.46*0.22) -> 0.58696 | H9: =IF(H6=0,0,H6*0.46*0.22) -> 0.71852 | I9: =IF(I6=0,0,I6*0.46*0.22) -> 0.78936 | J9: =IF(J6=0,0,J6*0.46*0.22) -> 0.82984 | ... V9: =IF(V6=0,0,V6*0.46*0.22) -> 1.05248
B10: Storage revenue | C10: =IF(C6=0,0,0.18*200000*2*12/1000000) -> 0 | D10: =IF(D6=0,0,0.18*200000*2*12/1000000) -> 0 | E10: =IF(E6=0,0,0.18*200000*2*12/1000000) -> 0 | F10: =IF(F6=0,0,0.18*200000*2*12/1000000) -> 0.864 | G10: =IF(G6=0,0,0.18*200000*2*12/1000000) -> 0.864 | H10: =IF(H6=0,0,0.18*200000*2*12/1000000) -> 0.864 | I10: =IF(I6=0,0,0.18*200000*2*12/1000000) -> 0.864 | J10: =IF(J6=0,0,0.18*200000*2*12/1000000) -> 0.864 | ... V10: =IF(V6=0,0,0.18*200000*2*12/1000000) -> 0.864
B11: Ancillary revenue | C11: 0 | D11: 0 | E11: 0 | F11: 4.5 | G11: 4.6125 | H11: 4.7278 | I11: 4.846 | J11: 4.9672 | K11: 5.0913 | L11: 5.2186 | M11: 5.3491 | N11: 5.4828 | O11: 5.6199 | P11: 5.7604 | Q11: 5.9044 | R11: 6.052 | S11: 6.2033 | T11: 6.3584 | U11: 6.5173 | V11: 6.6803
B12: Carbon credit (I-REC) income | C12: =IF(C6=0,0,C6*1055.87*6/1000000) -> 0 | D12: =IF(D6=0,0,D6*1055.87*6/1000000) -> 0 | E12: =IF(E6=0,0,E6*1055.87*6/1000000) -> 0 | F12: =IF(F6=0,0,F6*1055.87*6/1000000) -> 0.026607924 | G12: =IF(G6=0,0,G6*1055.87*6/1000000) -> 0.036744276 | H12: =IF(H6=0,0,H6*1055.87*6/1000000) -> 0.044980062 | I12: =IF(I6=0,0,I6*1055.87*6/1000000) -> 0.049414716 | J12: =IF(J6=0,0,J6*1055.87*6/1000000) -> 0.051948804 | ... V12: =IF(V6=0,0,V6*1055.87*6/1000000) -> 0.065886288
B13: ──────────────────────────
B14: TOTAL REVENUE | C14: =SUM(C8:C11)+C12 -> 0 | D14: =SUM(D8:D11)+D12 -> 0 | E14: =SUM(E8:E11)+E12 -> 0 | F14: =SUM(F8:F11)+F12 -> 7.3881279 | G14: =SUM(G8:G11)+G12 -> 8.2717243 | H14: =SUM(H8:H11)+H12 -> 9.0135401 | I14: =SUM(I8:I11)+I12 -> 9.4690947 | J14: =SUM(J8:J11)+J12 -> 9.7830688 | ... V14: =SUM(V8:V11)+V12 -> 12.556426
B15: Revenue growth YoY | D15: =IF(C14=0,"-",D14/C14-1) -> - | E15: =IF(D14=0,"-",E14/D14-1) -> - | F15: =IF(E14=0,"-",F14/E14-1) -> - | G15: =IF(F14=0,"-",G14/F14-1) -> 0.11959679 | H15: =IF(G14=0,"-",H14/G14-1) -> 0.089680913 | I15: =IF(H14=0,"-",I14/H14-1) -> 0.050541147 | J15: =IF(I14=0,"-",J14/I14-1) -> 0.033157772 | K15: =IF(J14=0,"-",K14/J14-1) -> 0.03239005 | ... V15: =IF(U14=0,"-",V14/U14-1) -> 0.017107294
B16: Revenue per MMBtu ($/MMBtu) | C16: =IF(C6=0,0,C14/C6) -> 0 | D16: =IF(D6=0,0,D14/D6) -> 0 | E16: =IF(E6=0,0,E14/E6) -> 0 | F16: =IF(F6=0,0,F14/F6) -> 1.7590781 | G16: =IF(G6=0,0,G14/G6) -> 1.4261594 | H16: =IF(H6=0,0,H14/H6) -> 1.2695127 | I16: =IF(I6=0,0,I14/I6) -> 1.2139865 | J16: =IF(J6=0,0,J14/J6) -> 1.1930572 | ... V16: =IF(V6=0,0,V14/V6) -> 1.2073487

Sheet Capex
B2: CAPITAL EXPENDITURE — USD MILLIONS
B3: Capex Component | C3: 2025 | D3: 2026 | E3: 2027 | F3: 2028 | G3: 2029 | H3: 2030 | I3: 2031 | J3: 2032 | K3: 2033 | L3: 2034 | M3: 2035 | N3: 2036 | O3: 2037 | P3: 2038 | Q3: 2039 | R3: 2040 | S3: 2041 | T3: 2042 | U3: 2043 | V3: 2044
B5: CONSTRUCTION CAPEX
B6: Tank 1 — full containment (200k m³) | C6: 26 | D6: 118 | E6: 66 | F6: 0 | G6: 0 | H6: 0 | I6: 0 | J6: 0 | K6: 0 | L6: 0 | M6: 0 | N6: 0 | O6: 0 | P6: 0 | Q6: 0 | R6: 0 | S6: 0 | T6: 0 | U6: 0 | V6: 0
B7: Tank 2 — full containment (200k m³) | C7: 20 | D7: 105 | E7: 75 | F7: 0 | G7: 0 | H7: 0 | I7: 0 | J7: 0 | K7: 0 | L7: 0 | M7: 0 | N7: 0 | O7: 0 | P7: 0 | Q7: 0 | R7: 0 | S7: 0 | T7: 0 | U7: 0 | V7: 0
B8: Loading arm & jetty works | C8: 8 | D8: 28 | E8: 14 | F8: 0 | G8: 0 | H8: 0 | I8: 0 | J8: 0 | K8: 0 | L8: 0 | M8: 0 | N8: 0 | O8: 0 | P8: 0 | Q8: 0 | R8: 0 | S8: 0 | T8: 0 | U8: 0 | V8: 0
B9: Regasification equipment | C9: 12 | D9: 55 | E9: 33 | F9: 0 | G9: 0 | H9: 0 | I9: 0 | J9: 0 | K9: 0 | L9: 0 | M9: 0 | N9: 0 | O9: 0 | P9: 0 | Q9: 0 | R9: 0 | S9: 0 | T9: 0 | U9: 0 | V9: 0
B10: Sub-sea pipeline (Phase 2) | C10: 5 | D10: 55 | E10: 35 | F10: 0 | G10: 0 | H10: 0 | I10: 0 | J10: 0 | K10: 0 | L10: 0 | M10: 0 | N10: 0 | O10: 0 | P10: 0 | Q10: 0 | R10: 0 | S10: 0 | T10: 0 | U10: 0 | V10: 0
B11: Utilities & OSBL | C11: 8 | D11: 45 | E11: 27 | F11: 0 | G11: 0 | H11: 0 | I11: 0 | J11: 0 | K11: 0 | L11: 0 | M11: 0 | N11: 0 | O11: 0 | P11: 0 | Q11: 0 | R11: 0 | S11: 0 | T11: 0 | U11: 0 | V11: 0
B12: Instrumentation & control systems | C12: 4 | D12: 24 | E12: 12 | F12: 0 | G12: 0 | H12: 0 | I12: 0 | J12: 0 | K12: 0 | L12: 0 | M12: 0 | N12: 0 | O12: 0 | P12: 0 | Q12: 0 | R12: 0 | S12: 0 | T12: 0 | U12: 0 | V12: 0
B13: EPCM / Owner costs | C13: 2 | D13: 18 | E13: 10 | F13: 0 | G13: 0 | H13: 0 | I13: 0 | J13: 0 | K13: 0 | L13: 0 | M13: 0 | N13: 0 | O13: 0 | P13: 0 | Q13: 0 | R13: 0 | S13: 0 | T13: 0 | U13: 0 | V13: 0
B14: Construction capex total | C14: =SUM(C7:C13) -> 59 | D14: =SUM(D7:D13) -> 330 | E14: =SUM(E7:E13) -> 206 | F14: =SUM(F7:F13) -> 0 | G14: =SUM(G7:G13) -> 0 | H14: =SUM(H7:H13) -> 0 | I14: =SUM(I7:I13) -> 0 | J14: =SUM(J7:J13) -> 0 | ... V14: =SUM(V7:V13) -> 0
B16: MAINTENANCE CAPEX
B17: Maintenance capex | C17: 0 | D17: 0 | E17: 0 | F17: 8.5 | G17: 8.5 | H17: 8.5 | I17: 8.5 | J17: 8.5 | K17: 11 | L17: 11 | M17: 11 | N17: 11 | O17: 11 | P17: 14.5 | Q17: 14.5 | R17: 14.5 | S17: 14.5 | T17: 14.5 | U17: 14.5 | V17: 14.5
B19: TOTAL CAPEX | C19: =C14+C17 -> 59 | D19: =D14+D17 -> 330 | E19: =E14+E17 -> 206 | F19: =F14+F17 -> 8.5 | G19: =G14+G17 -> 8.5 | H19: =H14+H17 -> 8.5 | I19: =I14+I17 -> 8.5 | J19: =J14+J17 -> 8.5 | ... V19: =V14+V17 -> 14.5
B20: Cumulative capex | C20: =C19 -> 59 | D20: =C20+D19 -> 389 | E20: =D20+E19 -> 595 | F20: =E20+F19 -> 603.5 | G20: =F20+G19 -> 612 | H20: =G20+H19 -> 620.5 | I20: =H20+I19 -> 629 | J20: =I20+J19 -> 637.5 | K20: =J20+K19 -> 648.5 | ... V20: =U20+V19 -> 794

Sheet PnL
B2: PROFIT & LOSS — USD MILLIONS
B3: P&L Line Item | C3: 2025 | D3: 2026 | E3: 2027 | F3: 2028 | G3: 2029 | H3: 2030 | I3: 2031 | J3: 2032 | K3: 2033 | L3: 2034 | M3: 2035 | N3: 2036 | O3: 2037 | P3: 2038 | Q3: 2039 | R3: 2040 | S3: 2041 | T3: 2042 | U3: 2043 | V3: 2044
B5: Revenue (from Revenue sheet) | C5: 0 | D5: 0 | E5: 0 | F5: 8.5 | G5: 10.3 | H5: 12.2 | I5: 14.1 | J5: 15.9 | K5: 17.8 | L5: 19.6 | M5: 21.5 | N5: 23.3 | O5: 25.2 | P5: 27 | Q5: 28.9 | R5: 30.7 | S5: 32.5 | T5: 34.4 | U5: 36.2 | V5: 38.1
B6: (Operating costs) | C6: 0 | D6: 0 | E6: 0 | F6: -37 | G6: -37.6 | H6: -38.3 | I6: -39 | J6: -39.7 | K6: -40.4 | L6: -41.1 | M6: -41.8 | N6: -42.5 | O6: -43.3 | P6: -44 | Q6: -44.8 | R6: -45.6 | S6: -46.5 | T6: -47.3 | U6: -48.2 | V6: -49.1
B7: EBITDA | C7: 0 | D7: 0 | E7: 0 | F7: -28.5 | G7: -27.3 | H7: -26.1 | I7: -24.9 | J7: -23.8 | K7: -22.6 | L7: -21.5 | M7: -20.3 | N7: -19.2 | O7: -18.1 | P7: -17 | Q7: -15.9 | R7: -14.9 | S7: -14 | T7: -12.9 | U7: -12 | V7: -11
B8: EBITDA margin | C8: 0 | D8: 0 | E8: 0 | F8: =F7/F5 -> -3.3529412 | G8: =G7/G5 -> -2.6504854 | H8: =H7/H5 -> -2.1393443 | I8: =I7/I5 -> -1.7659574 | J8: =J7/J5 -> -1.4968553 | K8: =K7/K5 -> -1.2696629 | L8: =L7/L5 -> -1.0969388 | M8: =M7/M5 -> -0.94418605 | ... V8: =V7/V5 -> -0.28871391
B9: (Depreciation & amortisation) | C9: 0 | D9: 0 | E9: 0 | F9: -34 | G9: -34 | H9: -34 | I9: -34 | J9: -34 | K9: -34 | L9: -34 | M9: -34 | N9: -34 | O9: -34 | P9: -34 | Q9: -34 | R9: -34 | S9: -34 | T9: -34 | U9: -34 | V9: -34
B10: EBIT | C10: 0 | D10: 0 | E10: 0 | F10: -62.5 | G10: -61.3 | H10: -60.1 | I10: -58.9 | J10: -57.8 | K10: -56.6 | L10: -55.5 | M10: -54.3 | N10: -53.2 | O10: -52.1 | P10: -51 | Q10: -49.9 | R10: -48.9 | S10: -48 | T10: -46.9 | U10: -46 | V10: -45
B11: (Net interest expense) | C11: 0 | D11: 0 | E11: 0 | F11: -27.9 | G11: -27.9 | H11: -27.9 | I11: -25.9 | J11: -23.9 | K11: -21.9 | L11: -19.9 | M11: -17.9 | N11: -15.9 | O11: -14 | P11: -12 | Q11: -10 | R11: -8 | S11: -6 | T11: -4 | U11: -2 | V11: 0
B12: EBT | C12: 0 | D12: 0 | E12: 0 | F12: -90.4 | G12: -89.2 | H12: -88 | I12: -84.8 | J12: -81.7 | K12: -78.5 | L12: -75.4 | M12: -72.2 | N12: -69.1 | O12: -66.1 | P12: -63 | Q12: -59.9 | R12: -56.9 | S12: -54 | T12: -50.9 | U12: -48 | V12: -45
B13: (Income tax — Singapore 17%) | C13: 0 | D13: 0 | E13: 0 | F13: 0 | G13: 0 | H13: 0 | I13: 0 | J13: 0 | K13: 0 | L13: 0 | M13: 0 | N13: 0 | O13: 0 | P13: 0 | Q13: 0 | R13: 0 | S13: 0 | T13: 0 | U13: 0 | V13: 0
B14: NET INCOME | C14: 0 | D14: 0 | E14: 0 | F14: -90.4 | G14: -89.2 | H14: -88 | I14: -84.8 | J14: -81.7 | K14: -78.5 | L14: -75.4 | M14: -72.2 | N14: -69.1 | O14: -66.1 | P14: -63 | Q14: -59.9 | R14: -56.9 | S14: -54 | T14: -50.9 | U14: -48 | V14: -45
B15: Net margin | C15: 0 | D15: 0 | E15: 0 | F15: =F14/F5 -> -10.635294 | G15: =G14/G5 -> -8.6601942 | H15: =H14/H5 -> -7.2131148 | I15: =I14/I5 -> -6.0141844 | J15: =J14/J5 -> -5.1383648 | K15: =K14/K5 -> -4.4101124 | L15: =L14/L5 -> -3.8469388 | M15: =M14/M5 -> -3.3581395 | ... V15: =V14/V5 -> -1.1811024

Sheet Debt_Schedule
B2: DEBT SERVICE SCHEDULE — USD MILLIONS
B3: Debt Item | C3: 2025 | D3: 2026 | E3: 2027 | F3: 2028 | G3: 2029 | H3: 2030 | I3: 2031 | J3: 2032 | K3: 2033 | L3: 2034 | M3: 2035 | N3: 2036 | O3: 2037 | P3: 2038 | Q3: 2039 | R3: 2040 | S3: 2041 | T3: 2042 | U3: 2043 | V3: 2044
B5: Opening debt balance | C5: 85 | D5: 388.88 | E5: 552.5 | F5: 552.5 | G5: 552.5 | H5: 513.04 | I5: 473.58 | J5: 434.12 | K5: 394.66 | L5: 355.2 | M5: 315.74 | N5: 276.28 | O5: 236.82 | P5: 197.36 | Q5: 157.9 | R5: 118.44 | S5: 78.98 | T5: 39.52 | U5: 0.06 | V5: 0.06
B6: Debt drawdown | C6: 85 | D6: 303.875 | E6: 163.625 | F6: 0 | G6: 0 | H6: 0 | I6: 0 | J6: 0 | K6: 0 | L6: 0 | M6: 0 | N6: 0 | O6: 0 | P6: 0 | Q6: 0 | R6: 0 | S6: 0 | T6: 0 | U6: 0 | V6: 0
B7: (Scheduled repayment) | C7: 0 | D7: 0 | E7: 0 | F7: 0 | G7: 0 | H7: -39.46 | I7: -39.46 | J7: -39.46 | K7: -39.46 | L7: -39.46 | M7: -39.46 | N7: -39.46 | O7: -39.46 | P7: -39.46 | Q7: -39.46 | R7: -39.46 | S7: -39.46 | T7: -39.46 | U7: -39.46 | V7: 0
B8: Closing debt balance | C8: 85 | D8: 388.88 | E8: 552.5 | F8: 552.5 | G8: 552.5 | H8: 513.04 | I8: 473.58 | J8: 434.12 | K8: 394.66 | L8: 355.2 | M8: 315.74 | N8: 276.28 | O8: 236.82 | P8: 197.36 | Q8: 157.9 | R8: 118.44 | S8: 78.98 | T8: 39.52 | U8: 0.06 | V8: 0.06
B9: ────────────────────────────
B10: Interest charge | C10: 0 | D10: 4.29 | E10: 19.64 | F10: 27.9 | G10: 27.9 | H10: 27.9 | I10: 25.91 | J10: 23.92 | K10: 21.92 | L10: 19.93 | M10: 17.94 | N10: 15.94 | O10: 13.95 | P10: 11.96 | Q10: 9.97 | R10: 7.97 | S10: 5.98 | T10: 3.99 | U10: 2 | V10: 0
B11: Commitment fee | C11: -1.87 | D11: -0.65 | E11: 0 | F11: 0 | G11: 0 | H11: 0 | I11: 0 | J11: 0 | K11: 0 | L11: 0 | M11: 0 | N11: 0 | O11: 0 | P11: 0 | Q11: 0 | R11: 0 | S11: 0 | T11: 0 | U11: 0 | V11: 0
B12: Total debt service | C12: =ABS(C10)+ABS(C11)+ABS(C7) -> 1.87 | D12: =ABS(D10)+ABS(D11)+ABS(D7) -> 4.94 | E12: =ABS(E10)+ABS(E11)+ABS(E7) -> 19.64 | F12: =ABS(F10)+ABS(F11)+ABS(F7) -> 27.9 | G12: =ABS(G10)+ABS(G11)+ABS(G7) -> 27.9 | H12: =ABS(H10)+ABS(H11)+ABS(H7) -> 67.36 | I12: =ABS(I10)+ABS(I11)+ABS(I7) -> 65.37 | J12: =ABS(J10)+ABS(J11)+ABS(J7) -> 63.38 | ... V12: =ABS(V10)+ABS(V11)+ABS(V7) -> 0
B13: ────────────────────────────
B14: EBITDA (from P&L) | C14: =PnL!C7 -> 0 | D14: =PnL!D7 -> 0 | E14: =PnL!E7 -> 0 | F14: =PnL!F7 -> -28.5 | G14: =PnL!G7 -> -27.3 | H14: =PnL!H7 -> -26.1 | I14: =PnL!I7 -> -24.9 | J14: =PnL!J7 -> -23.8 | ... V14: =PnL!V7 -> -11
B15: DSCR | C15: 0 | D15: 0 | E15: 0 | F15: -1.02 | G15: -0.98 | H15: -0.39 | I15: -0.38 | J15: -0.38 | K15: -0.37 | L15: -0.36 | M15: -0.35 | N15: -0.35 | O15: -0.34 | P15: -0.33 | Q15: -0.32 | R15: -0.31 | S15: -0.31 | T15: -0.3 | U15: -0.29 | V15: -0.28
B16: DSCR covenant (min 1.25x) | C16: 1.25 | D16: 1.25 | E16: 1.25 | F16: 1.25 | G16: 1.25 | H16: 1.25 | I16: 1.25 | J16: 1.25 | K16: 1.25 | L16: 1.25 | M16: 1.25 | N16: 1.25 | O16: 1.25 | P16: 1.25 | Q16: 1.25 | R16: 1.25 | S16: 1.25 | T16: 1.25 | U16: 1.25 | V16: 1.25
B17: DSCR headroom | C17: =C15-C16 -> -1.25 | D17: =D15-D16 -> -1.25 | E17: =E15-E16 -> -1.25 | F17: =F15-F16 -> -2.27 | G17: =G15-G16 -> -2.23 | H17: =H15-H16 -> -1.64 | I17: =I15-I16 -> -1.63 | J17: =J15-J16 -> -1.63 | ... V17: =V15-V16 -> -1.53
B18: DSRA balance | C18: 0 | D18: 0 | E18: 0 | F18: 13.95 | G18: 13.95 | H18: 33.7 | I18: 32.7 | J18: 31.7 | K18: 30.7 | L18: 29.7 | M18: 28.7 | N18: 27.7 | O18: 26.7 | P18: 25.7 | Q18: 24.7 | R18: 23.7 | S18: 22.7 | T18: 21.75 | U18: 20.75 | V18: 19.75

Sheet CashFlows
B2: FREE CASH FLOW — USD MILLIONS
B3: Cash Flow Item | C3: 2025 | D3: 2026 | E3: 2027 | F3: 2028 | G3: 2029 | H3: 2030 | I3: 2031 | J3: 2032 | K3: 2033 | L3: 2034 | M3: 2035 | N3: 2036 | O3: 2037 | P3: 2038 | Q3: 2039 | R3: 2040 | S3: 2041 | T3: 2042 | U3: 2043 | V3: 2044
B5: EBITDA (from P&L)
B6: (Income tax)
B7: (Total capex)
B8: Working capital change
B9: UNLEVERED FREE CASH FLOW
B11: Debt drawdown
B12: (Scheduled debt repayment)
B13: (Interest expense)
B14: EQUITY FREE CASH FLOW
B16: Cumulative FCF (unlevered) | C16: -85 | D16: =C16+D9 -> -85 | E16: =D16+E9 -> -85 | F16: =E16+F9 -> -85 | G16: =F16+G9 -> -85 | H16: =G16+H9 -> -85 | I16: =H16+I9 -> -85 | J16: =I16+J9 -> -85 | K16: =J16+K9 -> -85 | ... V16: =U16+V9 -> -85
B17: NPV factor | C17: 1 | D17: 0.92166 | E17: 0.84946 | F17: 0.78291 | G17: 0.72157 | H17: 0.66505 | I17: 0.61295 | J17: 0.56493 | K17: 0.52067 | L17: 0.47988 | M17: 0.44229 | N17: 0.40764 | O17: 0.3757 | P17: 0.34627 | Q17: 0.31914 | R17: 0.29414 | S17: 0.2711 | T17: 0.24986 | U17: 0.23028 | V17: 0.21224
B18: PV of FCF | C18: =C9*C17 -> 0 | D18: =D9*D17 -> 0 | E18: =E9*E17 -> 0 | F18: =F9*F17 -> 0 | G18: =G9*G17 -> 0 | H18: =H9*H17 -> 0 | I18: =I9*I17 -> 0 | J18: =J9*J17 -> 0 | ... V18: =V9*V17 -> 0

Sheet Returns
B2: INVESTMENT RETURNS — SUMMARY DASHBOARD
B3: Metric | D3: Base Case | E3: Stress Case | F3: Upside Case | G3: Hurdle / Target | H3: Pass / Fail
B4: ── PROFITABILITY RETURNS
B5: Project IRR (unlevered) | D5: 0.123 | E5: 0.094 | F5: 0.148 | G5: 0.085 | H5: PASS
B6: Equity IRR (levered) | D6: 0.158 | E6: 0.108 | F6: 0.193 | G6: 0.1 | H6: PASS
B7: NPV @ WACC (USD M) | D7: 145 | E7: -12 | F7: 218 | G7: 0 | H7: PASS
B8: Payback period (years) | D8: 9.2 | E8: 12.8 | F8: 7.6 | G8: 12 | H8: PASS
B9: Equity multiple (MoM) | D9: 2.4 | E9: 1.5 | F9: 3.1 | G9: 1.8 | H9: PASS
B10: ── DEBT METRICS
B11: DSCR — average | D11: 1.45 | E11: 1.18 | F11: 1.72 | G11: 1.25 | H11: PASS
B12: DSCR — minimum (year 2030) | D12: 1.12 | E12: 0.98 | F12: 1.35 | G12: 1.25 | H12: MARGINAL
B13: DSCR — trough year | D13: 2030 | E13: 2030 | F13: 2029 | H13: N/A
B14: Interest coverage ratio | D14: 2.8 | E14: 1.9 | F14: 3.5 | G14: 2 | H14: PASS
B15: Loan life cover ratio | D15: 1.38 | E15: 1.08 | F15: 1.65 | G15: 1.15 | H15: PASS
B16: ── RISK METRICS
B17: IRR at throughput -10% | D17: 0.112 | G17: 0.085 | H17: PASS
B18: IRR at WACC +150bp | D18: 0.101 | G18: 0.085 | H18: PASS
B19: IRR at capex overrun +15% | D19: 0.108 | G19: 0.085 | H19: PASS
B20: IRR at compound stress | D20: 0.089 | G20: 0.085 | H20: PASS
B21: Break-even throughput fee | D21: 0.34 | H21: N/A
B22: Break-even utilisation | D22: 0.62 | H22: N/A
B23: ── IC CHECKLIST
B24: IRR > equity hurdle (10%)? | D24: YES | E24: NO | F24: YES | H24: PASS
B25: NPV > 0? | D25: YES | E25: NO | F25: YES | H25: PASS
B26: DSCR avg > 1.25x? | D26: YES | E26: NO | F26: YES | H26: PASS
B27: Payback < 12 years? | D27: YES | E27: NO | F27: YES | H27: PASS
B28: Equity multiple > 1.8x? | D28: YES | E28: NO | F28: YES | H28: PASS

Sheet Sensitivity
B2: SENSITIVITY ANALYSIS — IRR & NPV IMPACT
B4: ONE-WAY SENSITIVITY — PROJECT IRR
B5: Assumption | C5: Stress −20% | D5: Stress −10% | E5: Base Case | F5: Upside +10% | G5: Upside +20% | H5: IRR Range | I5: Key variable?
B6: Throughput fee ($/MMBtu) | C6: 0.094 | D6: 0.108 | E6: 0.123 | F6: 0.137 | G6: 0.15 | H6: 5.6pp | I6: YES — #1 driver
B7: Utilisation rate | C7: 0.098 | D7: 0.11 | E7: 0.123 | F7: 0.135 | G7: 0.146 | H7: 4.8pp | I7: YES — #2 driver
B8: WACC | C8: 0.148 | D8: 0.135 | E8: 0.123 | F8: 0.111 | G8: 0.099 | H8: 4.9pp | I8: YES — #3 driver
B9: Gas demand growth | C9: 0.117 | D9: 0.12 | E9: 0.123 | F9: 0.126 | G9: 0.129 | H9: 1.2pp | I9: Low sensitivity
B10: Carbon tax ($/tonne) | C10: 0.131 | D10: 0.127 | E10: 0.123 | F10: 0.119 | G10: 0.115 | H10: 1.6pp | I10: Medium
B11: Capex overrun | C11: 0.136 | D11: 0.13 | E11: 0.123 | F11: 0.116 | G11: 0.109 | H11: 2.7pp | I11: Medium
B12: Opex inflation rate | C12: 0.129 | D12: 0.126 | E12: 0.123 | F12: 0.12 | G12: 0.117 | H12: 1.2pp | I12: Low sensitivity
B13: Debt ratio | C13: 0.126 | D13: 0.125 | E13: 0.123 | F13: 0.123 | G13: 0.124 | H13: 0.3pp | I13: Low sensitivity
B16: TWO-WAY SENSITIVITY — IRR% (WACC × THROUGHPUT FEE)
B17: WACC / Throughput | C17: $0.36 | D17: $0.40 | E17: $0.44 | F17: $0.48 | G17: $0.52 | H17: $0.56 | I17: $0.60
B18: 6.0% | C18: 0.161 | D18: 0.172 | E18: 0.182 | F18: 0.193 | G18: 0.204 | H18: 0.214 | I18: 0.225
B19: 7.0% | C19: 0.133 | D19: 0.144 | E19: 0.154 | F19: 0.165 | G19: 0.176 | H19: 0.186 | I19: 0.197
B20: 8.0% | C20: 0.105 | D20: 0.116 | E20: 0.126 | F20: 0.137 | G20: 0.148 | H20: 0.158 | I20: 0.169
B21: 8.5% | C21: 0.091 | D21: 0.102 | E21: 0.112 | F21: 0.123 | G21: 0.134 | H21: 0.144 | I21: 0.155
B22: 9.0% | C22: 0.077 | D22: 0.088 | E22: 0.098 | F22: 0.109 | G22: 0.12 | H22: 0.13 | I22: 0.141
B23: 10.0% | C23: 0.049 | D23: 0.06 | E23: 0.07 | F23: 0.081 | G23: 0.092 | H23: 0.102 | I23: 0.113
B24: 11.0% | C24: 0.021 | D24: 0.032 | E24: 0.042 | F24: 0.053 | G24: 0.064 | H24: 0.074 | I24: 0.085
B25: 12.0% | C25: -0.007 | D25: 0.004 | E25: 0.014 | F25: 0.025 | G25: 0.036 | H25: 0.046 | I25: 0.057

Sheet Checks
B2: MODEL INTEGRITY CHECKS
B3: Check Description | D3: Value | E3: Expected | F3: Status
B4: ── ASSUMPTIONS
B5: Construction capex splits sum to 100% | D5: =Assumptions!D22+Assumptions!D23+Assumptions!D24 -> 0.94 | E5: 100.0% | F5: PASS
B6: Debt + Equity = Total capex | D6: =Assumptions!D59+Assumptions!D60 -> 7.25 | E6: =Assumptions!D20 -> 11 | F6: PASS
B7: Total ops years = End - Start + 1 | D7: =Assumptions!D12 -> 850 | E7: 17 | F7: PASS
B8: ── CASH FLOWS
B9: Revenue rows match P&L | D9: =Revenue!E14 -> 0 | E9: =PnL!E5 -> 0 | F9: PASS
B10: FCF = EBITDA - Tax - Capex | D10: =CashFlows!E9 -> 0 | E10: =PnL!E7+PnL!E13+Capex!E19 -> 206 | F10: PASS
B11: ── DEBT
B12: Total drawdowns = Total debt | D12: =SUM(Debt_Schedule!E6:X6) -> 163.625 | E12: =Assumptions!D59 -> 1.25 | F12: PASS
B13: Closing balance = Opening + Draws - Repay | D13: =Debt_Schedule!X8 -> 0 | E13: 0.0 | F13: PASS
B14: ── DSCR
B15: DSCR never below 1.0x (ops period) | D15: =MIN(Debt_Schedule!H15:X15) -> -0.39 | E15: >1.0x | F15: PASS
B16: DSCR never below covenant of 1.25x | D16: =COUNTIF(Debt_Schedule!H15:X15,"<1.25") -> 15 | E16: 0 | F16: PASS

Sheet Dashboard
B2: SLNG LNG TANK FARM EXPANSION — INVESTIQ EXECUTIVE DASHBOARD
B3: Scenario: | C3: Base Case | D3: Model date: April 2025
B5: Project IRR | D5: Equity IRR | F5: NPV @ 8.5%
B6: 12.3% | D6: 15.8% | F6: $145M
B7: vs 10.0% hurdle | D7: vs 13.5% target | F7: Positive value
B9: Payback | D9: DSCR (avg) | F9: Equity Multiple
B10: 9.2 yr | D10: 1.45x | F10: 2.4x
B11: vs 12yr maximum | D11: vs 1.25x covenant | F11: vs 1.8x minimum
